Workbook

Sheet Graphique
A1: Pseudo -> | B1: Breizhkanaki | D1: Présentation du classement ou qu'est ce que le classement RPL adapté au Poker -> Présentation du Classement RPL adapté au Club de Poker
A3: =BA48 -> RPL actuel : 1512 | C3: =BA49 -> RPL du club : 1575
S4: 🧮 Échelle RPL du PMPC
S5: Niveau | T5: RPL estimé | U5: % de victoire attendu vs RPL du club (1588) | V5: Description
S6: Débutant du club | T6: < 1470 | U6: ~35 % | V6: Découvre encore les dynamiques du poker live : tailles de mise, lecture des adversaires, discipline préflop. Beaucoup d’enthousiasme, mais encore des erreurs structurelles. Objectif : acquérir patience et rigueur.
S7: Joueur en apprentissage | T7: 1470–1530 | U7: 40–46 % | V7: Commence à comprendre les bases stratégiques (position, ranges, cotes). Peut briller par moments, mais manque encore de constance. Gagne surtout sur la surprise.
S8: Joueur intermédiaire | T8: 1530–1590 | U8: 47–53 % | V8: Solide, comprend la plupart des situations standards. Ses performances deviennent prévisibles et régulières. Peut parfois manquer de prise d’initiative ou d’agressivité calculée.
S9: Bon joueur du club | T9: 1590–1660 | U9: 54–60 % | V9: Structure de jeu claire, gestion de tapis cohérente, meilleure lecture des tells et des rythmes. Commence à adapter son jeu selon le type de table.
S10: Joueur confirmé | T10: 1660–1730 | U10: 61–68 % | V10: Vision stratégique complète, maîtrise de la pression et du mental. Constamment dangereux. Souvent dans les phases finales ou dans le top 5.
S11: Excellent joueur du club | T11: 1730–1780 | U11: 70–76 % | V11: Régulier, réfléchi, patient. Comprend intuitivement la dynamique de table. Difficile à bluffer. Capable d’analyser froidement chaque situation.
S12: Joueur dominant | T12: 1780–1850 | U12: 77–83 % | V12: Très grande stabilité mentale, lecture des ranges précises, compréhension fine des probabilités. Influence la table par sa simple présence. Peut affronter des pros.
S13: Joueur exceptionnel | T13: 1850–1900 | U13: 84–88 % | V13: Combine technique, psychologie et discipline. Capable d’affronter des pros et de tenir la cadence sur le long terme. C’est la passerelle naturelle vers les circuits compétitifs.
S14: Limite théorique (~1980) | T14: 1900+ | U14: 89–92 % | V14: Domination quasi totale dans le contexte du club. Pour continuer à progresser, il faut se confronter à un field plus relevé (tournois régionaux, pros, circuits officiels).
B48: {=IF(INDEX(Feuil1!$B$4:$AY$103, MATCH($B$1, Feuil1!$A$4:$A$103,0), COLUMN()-1)="", NA(), INDEX(Feuil1!$B$4:$AY$103, MATCH($B$1, Feuil1!$A$4:$A$103,0), COLUMN()-1))} -> 1500 | C48: {=IF(INDEX(Feuil1!$B$4:$AY$103, MATCH($B$1, Feuil1!$A$4:$A$103,0), COLUMN()-1)="", NA(), INDEX(Feuil1!$B$4:$AY$103, MATCH($B$1, Feuil1!$A$4:$A$103,0), COLUMN()-1))} -> 1507.9466 | D48: {=IF(INDEX(Feuil1!$B$4:$AY$103, MATCH($B$1, Feuil1!$A$4:$A$103,0), COLUMN()-1)="", NA(), INDEX(Feuil1!$B$4:$AY$103, MATCH($B$1, Feuil1!$A$4:$A$103,0), COLUMN()-1))} -> 1502.27 | E48: {=IF(INDEX(Feuil1!$B$4:$AY$103, MATCH($B$1, Feuil1!$A$4:$A$103,0), COLUMN()-1)="", NA(), INDEX(Feuil1!$B$4:$AY$103, MATCH($B$1, Feuil1!$A$4:$A$103,0), COLUMN()-1))} -> 1499.6493 | F48: {=IF(INDEX(Feuil1!$B$4:$AY$103, MATCH($B$1, Feuil1!$A$4:$A$103,0), COLUMN()-1)="", NA(), INDEX(Feuil1!$B$4:$AY$103, MATCH($B$1, Feuil1!$A$4:$A$103,0), COLUMN()-1))} -> 1498.9897 | G48: {=IF(INDEX(Feuil1!$B$4:$AY$103, MATCH($B$1, Feuil1!$A$4:$A$103,0), COLUMN()-1)="", NA(), INDEX(Feuil1!$B$4:$AY$103, MATCH($B$1, Feuil1!$A$4:$A$103,0), COLUMN()-1))} -> 1498.9897 | H48: {=IF(INDEX(Feuil1!$B$4:$AY$103, MATCH($B$1, Feuil1!$A$4:$A$103,0), COLUMN()-1)="", NA(), INDEX(Feuil1!$B$4:$AY$103, MATCH($B$1, Feuil1!$A$4:$A$103,0), COLUMN()-1))} -> 1504.494 | I48: {=IF(INDEX(Feuil1!$B$4:$AY$103, MATCH($B$1, Feuil1!$A$4:$A$103,0), COLUMN()-1)="", NA(), INDEX(Feuil1!$B$4:$AY$103, MATCH($B$1, Feuil1!$A$4:$A$103,0), COLUMN()-1))} -> 1513.7916 | ... AY48: {=IF(INDEX(Feuil1!$B$4:$AY$103, MATCH($B$1, Feuil1!$A$4:$A$103,0), COLUMN()-1)="", NA(), INDEX(Feuil1!$B$4:$AY$103, MATCH($B$1, Feuil1!$A$4:$A$103,0), COLUMN()-1))} -> #N/A | AZ48: =IFERROR(__xludf.DUMMYFUNCTION("INDEX(FILTER($B48:AY48, ISNUMBER($B48:AY48)), COUNTA(FILTER($B48:AY48, ISNUMBER($B48:AY48))))"),1512.09711887037) -> 1512.0971 | BA48: ="RPL actuel : "&ROUND(AZ48,0) -> RPL actuel : 1512
A49: RPL du club | B49: {=IF(INDEX(Feuil1!$B$4:$AY$103, MATCH($A$49, Feuil1!$A$4:$A$103,0), COLUMN()-1)="", NA(), INDEX(Feuil1!$B$4:$AY$103, MATCH($A$49, Feuil1!$A$4:$A$103,0), COLUMN()-1))} -> 1500 | C49: {=IF(INDEX(Feuil1!$B$4:$AY$103, MATCH($A$49, Feuil1!$A$4:$A$103,0), COLUMN()-1)="", NA(), INDEX(Feuil1!$B$4:$AY$103, MATCH($A$49, Feuil1!$A$4:$A$103,0), COLUMN()-1))} -> 1513.2898 | D49: {=IF(INDEX(Feuil1!$B$4:$AY$103, MATCH($A$49, Feuil1!$A$4:$A$103,0), COLUMN()-1)="", NA(), INDEX(Feuil1!$B$4:$AY$103, MATCH($A$49, Feuil1!$A$4:$A$103,0), COLUMN()-1))} -> 1523.7014 | E49: {=IF(INDEX(Feuil1!$B$4:$AY$103, MATCH($A$49, Feuil1!$A$4:$A$103,0), COLUMN()-1)="", NA(), INDEX(Feuil1!$B$4:$AY$103, MATCH($A$49, Feuil1!$A$4:$A$103,0), COLUMN()-1))} -> 1531.9672 | F49: {=IF(INDEX(Feuil1!$B$4:$AY$103, MATCH($A$49, Feuil1!$A$4:$A$103,0), COLUMN()-1)="", NA(), INDEX(Feuil1!$B$4:$AY$103, MATCH($A$49, Feuil1!$A$4:$A$103,0), COLUMN()-1))} -> 1541.5944 | G49: {=IF(INDEX(Feuil1!$B$4:$AY$103, MATCH($A$49, Feuil1!$A$4:$A$103,0), COLUMN()-1)="", NA(), INDEX(Feuil1!$B$4:$AY$103, MATCH($A$49, Feuil1!$A$4:$A$103,0), COLUMN()-1))} -> 1548.7203 | H49: {=IF(INDEX(Feuil1!$B$4:$AY$103, MATCH($A$49, Feuil1!$A$4:$A$103,0), COLUMN()-1)="", NA(), INDEX(Feuil1!$B$4:$AY$103, MATCH($A$49, Feuil1!$A$4:$A$103,0), COLUMN()-1))} -> 1548.35 | I49: {=IF(INDEX(Feuil1!$B$4:$AY$103, MATCH($A$49, Feuil1!$A$4:$A$103,0), COLUMN()-1)="", NA(), INDEX(Feuil1!$B$4:$AY$103, MATCH($A$49, Feuil1!$A$4:$A$103,0), COLUMN()-1))} -> 1556.3076 | ... AY49: {=IF(INDEX(Feuil1!$B$4:$AY$103, MATCH($A$49, Feuil1!$A$4:$A$103,0), COLUMN()-1)="", NA(), INDEX(Feuil1!$B$4:$AY$103, MATCH($A$49, Feuil1!$A$4:$A$103,0), COLUMN()-1))} -> #N/A | AZ49: =IFERROR(__xludf.DUMMYFUNCTION("INDEX(FILTER(Feuil1!C103:AY103, ISNUMBER(Feuil1!C103:AY103)), COUNTA(FILTER(Feuil1!C103:AY103, ISNUMBER(Feuil1!C103:AY103))))"),1574.889521695299) -> 1574.8895 | BA49: ="RPL du club : "&ROUND(AZ49,0) -> RPL du club : 1575

Sheet Classement RPL PMPC
A1: CLASSEMENT | B1: PSEUDO | C1: RPL | E1: Nouveau RPL = R+K×(S−E) R = ancien RPL du joueur K = constante de progression (32, 24 ou 16 selon le nbr de parties) S = √(Nb_Joueurs + 1) / Position -> score réel (place dans le tournoi) E = 1 / (1 + 10^((RPL_Du_Club - RPL_Precedent)/400)) -> score attendu
A2: 1 | B2: {=IFERROR(INDEX(Feuil1!A$4:A$102,MATCH('Classement RPL PMPC'!A2,Feuil1!BA$4:BA$102,0)),"")} -> Meruem | C2: =IFERROR(LARGE(Feuil1!AZ$4:AZ$102, ROWS('Classement RPL PMPC'!C$1:C1)),"") -> 1722.7938 | E2: Formule : Nouveau RPL = RPL_Precedent + K * (√(Nb_Joueurs + 1) / Position - 1 / (1 + 10^((RPL_Du_Club - RPL_Precedent)/400)))
A3: 2 | B3: {=IFERROR(INDEX(Feuil1!A$4:A$102,MATCH('Classement RPL PMPC'!A3,Feuil1!BA$4:BA$102,0)),"")} -> MinnieLoucas | C3: =IFERROR(LARGE(Feuil1!AZ$4:AZ$102, ROWS('Classement RPL PMPC'!C$1:C2)),"") -> 1687.9488
A4: 3 | B4: {=IFERROR(INDEX(Feuil1!A$4:A$102,MATCH('Classement RPL PMPC'!A4,Feuil1!BA$4:BA$102,0)),"")} -> Loucas | C4: =IFERROR(LARGE(Feuil1!AZ$4:AZ$102, ROWS('Classement RPL PMPC'!C$1:C3)),"") -> 1659.639
A5: 4 | B5: {=IFERROR(INDEX(Feuil1!A$4:A$102,MATCH('Classement RPL PMPC'!A5,Feuil1!BA$4:BA$102,0)),"")} -> Ronkout | C5: =IFERROR(LARGE(Feuil1!AZ$4:AZ$102, ROWS('Classement RPL PMPC'!C$1:C4)),"") -> 1659.5039
A6: 5 | B6: {=IFERROR(INDEX(Feuil1!A$4:A$102,MATCH('Classement RPL PMPC'!A6,Feuil1!BA$4:BA$102,0)),"")} -> Gnaffron | C6: =IFERROR(LARGE(Feuil1!AZ$4:AZ$102, ROWS('Classement RPL PMPC'!C$1:C5)),"") -> 1640.8841
A7: 6 | B7: {=IFERROR(INDEX(Feuil1!A$4:A$102,MATCH('Classement RPL PMPC'!A7,Feuil1!BA$4:BA$102,0)),"")} -> PikaJul | C7: =IFERROR(LARGE(Feuil1!AZ$4:AZ$102, ROWS('Classement RPL PMPC'!C$1:C6)),"") -> 1626.4769
A8: 7 | B8: {=IFERROR(INDEX(Feuil1!A$4:A$102,MATCH('Classement RPL PMPC'!A8,Feuil1!BA$4:BA$102,0)),"")} -> Patrice | C8: =IFERROR(LARGE(Feuil1!AZ$4:AZ$102, ROWS('Classement RPL PMPC'!C$1:C7)),"") -> 1613.3524
A9: 8 | B9: {=IFERROR(INDEX(Feuil1!A$4:A$102,MATCH('Classement RPL PMPC'!A9,Feuil1!BA$4:BA$102,0)),"")} -> Schirou | C9: =IFERROR(LARGE(Feuil1!AZ$4:AZ$102, ROWS('Classement RPL PMPC'!C$1:C8)),"") -> 1610.3916
A10: 9 | B10: {=IFERROR(INDEX(Feuil1!A$4:A$102,MATCH('Classement RPL PMPC'!A10,Feuil1!BA$4:BA$102,0)),"")} -> Gwen | C10: =IFERROR(LARGE(Feuil1!AZ$4:AZ$102, ROWS('Classement RPL PMPC'!C$1:C9)),"") -> 1608.3473
A11: 10 | B11: {=IFERROR(INDEX(Feuil1!A$4:A$102,MATCH('Classement RPL PMPC'!A11,Feuil1!BA$4:BA$102,0)),"")} -> Cat | C11: =IFERROR(LARGE(Feuil1!AZ$4:AZ$102, ROWS('Classement RPL PMPC'!C$1:C10)),"") -> 1572.868
A12: 11 | B12: {=IFERROR(INDEX(Feuil1!A$4:A$102,MATCH('Classement RPL PMPC'!A12,Feuil1!BA$4:BA$102,0)),"")} -> Nicolas | C12: =IFERROR(LARGE(Feuil1!AZ$4:AZ$102, ROWS('Classement RPL PMPC'!C$1:C11)),"") -> 1564.2164
A13: 12 | B13: {=IFERROR(INDEX(Feuil1!A$4:A$102,MATCH('Classement RPL PMPC'!A13,Feuil1!BA$4:BA$102,0)),"")} -> Teddy | C13: =IFERROR(LARGE(Feuil1!AZ$4:AZ$102, ROWS('Classement RPL PMPC'!C$1:C12)),"") -> 1560.3759
A14: 13 | B14: {=IFERROR(INDEX(Feuil1!A$4:A$102,MATCH('Classement RPL PMPC'!A14,Feuil1!BA$4:BA$102,0)),"")} -> Howie | C14: =IFERROR(LARGE(Feuil1!AZ$4:AZ$102, ROWS('Classement RPL PMPC'!C$1:C13)),"") -> 1542.4309
... A101: 100 | B101: {=IFERROR(INDEX(Feuil1!A$4:A$102,MATCH('Classement RPL PMPC'!A101,Feuil1!BA$4:BA$102,0)),"")} | C101: =IFERROR(LARGE(Feuil1!AZ$4:AZ$102, ROWS('Classement RPL PMPC'!C$1:C100)),"")

Sheet Résultats des tournois
A1: Saison 25/26 | B1: S36 | C1: S37 | D1: S38 | E1: S39 | F1: S40 | G1: S41 | H1: S42 | I1: S43 | J1: S44 | K1: S45 | L1: S46 | M1: S47 | N1: S48 | O1: S49 | P1: S50 | Q1: S51 | R1: S52 | S1: S1 | T1: S2 | U1: S3 | V1: S4 | W1: S5 | X1: S6 | Y1: S7 | Z1: S8 | AA1: S9 | AB1: S10 | AC1: S11 | AD1: S12 | AE1: S13 | AF1: S14 | AG1: S15 | AH1: S16 | AI1: S17 | AJ1: S18 | AK1: S19 | AL1: S20 | AM1: S21 | AN1: S22 | AO1: S23 | AP1: S24 | AQ1: S25 | AR1: S26 | AS1: S27 | AT1: S28 | AU1: S29 | AV1: S30 | AW1: S31 | AX1: S32
A2: Nbr de Joueurs -> | B2: =COUNTIF(B4:B102,"<>") -> 13 | C2: =COUNTIF(C4:C102,"<>") -> 11 | D2: =COUNTIF(D4:D102,"<>") -> 14 | E2: =COUNTIF(E4:E102,"<>") -> 11 | F2: =COUNTIF(F4:F102,"<>") -> 12 | G2: =COUNTIF(G4:G102,"<>") -> 12 | H2: =COUNTIF(H4:H102,"<>") -> 16 | I2: =COUNTIF(I4:I102,"<>") -> 10 | ... AX2: =COUNTIF(AX4:AX102,"<>") -> 0
A3: Nom du joueur | B3: Classement | C3: Classement | D3: Classement | E3: Classement | F3: Classement | G3: Classement | H3: Classement | I3: Classement | J3: Classement | K3: Classement | L3: Classement | M3: Classement | N3: Classement | O3: Classement | P3: Classement | Q3: Classement | R3: Classement | S3: Classement | T3: Classement | U3: Classement | V3: Classement | W3: Classement | X3: Classement | Y3: Classement | Z3: Classement | AA3: Classement | AB3: Classement | AC3: Classement | AD3: Classement | AE3: Classement | AF3: Classement | AG3: Classement | AH3: Classement | AI3: Classement | AJ3: Classement | AK3: Classement | AL3: Classement | AM3: Classement | AN3: Classement | AO3: Classement | AP3: Classement | AQ3: Classement | AR3: Classement | AS3: Classement | AT3: Classement | AU3: Classement | AV3: Classement | AW3: Classement | AX3: Classement | AY3: Nbr de parties jouées | AZ3: K dynamique
A4: Breizhkanaki | B4: 5 | C4: 11 | D4: 10 | E4: 8 | G4: 6 | H4: 5 | I4: 9 | AY4: =COUNTIF(B4:AX4,"<>") -> 7 | AZ4: =IF(AY4<=5,32,IF(AY4<=15,24,16)) -> 24
A5: Cat | D5: 9 | E5: 4 | F5: 6 | H5: 2 | I5: 8 | J5: 11 | K5: 14 | L5: 3 | AY5: =COUNTIF(B5:AX5,"<>") -> 8 | AZ5: =IF(AY5<=5,32,IF(AY5<=15,24,16)) -> 24
A6: Gnaffron | B6: 7 | C6: 9 | D6: 1 | E6: 6 | F6: 10 | G6: 7 | H6: 14 | I6: 5 | J6: 3 | K6: 7 | L6: 2 | AY6: =COUNTIF(B6:AX6,"<>") -> 11 | AZ6: =IF(AY6<=5,32,IF(AY6<=15,24,16)) -> 24
A7: Gwen | B7: 8 | C7: 10 | D7: 13 | F7: 1 | H7: 4 | J7: 8 | L7: 5 | AY7: =COUNTIF(B7:AX7,"<>") -> 7 | AZ7: =IF(AY7<=5,32,IF(AY7<=15,24,16)) -> 24
A8: Howie | B8: 2 | D8: 8 | AY8: =COUNTIF(B8:AX8,"<>") -> 2 | AZ8: =IF(AY8<=5,32,IF(AY8<=15,24,16)) -> 32
A9: Hyppo | B9: 13 | D9: 4 | AY9: =COUNTIF(B9:AX9,"<>") -> 2 | AZ9: =IF(AY9<=5,32,IF(AY9<=15,24,16)) -> 32
A10: Loucas | B10: 12 | D10: 3 | E10: 10 | G10: 11 | H10: 3 | I10: 3 | J10: 13 | K10: 2 | L10: 1 | AY10: =COUNTIF(B10:AX10,"<>") -> 9 | AZ10: =IF(AY10<=5,32,IF(AY10<=15,24,16)) -> 24
A11: Mat | D11: 6 | AY11: =COUNTIF(B11:AX11,"<>") -> 1 | AZ11: =IF(AY11<=5,32,IF(AY11<=15,24,16)) -> 32
A12: Meruem | B12: 3 | C12: 1 | D12: 2 | E12: 1 | F12: 12 | G12: 9 | H12: 13 | I12: 2 | J12: 6 | K12: 8 | L12: 10 | AY12: =COUNTIF(B12:AX12,"<>") -> 11 | AZ12: =IF(AY12<=5,32,IF(AY12<=15,24,16)) -> 24
A13: Micky | C13: 6 | F13: 9 | G13: 8 | H13: 12 | J13: 10 | K13: 12 | AY13: =COUNTIF(B13:AX13,"<>") -> 6 | AZ13: =IF(AY13<=5,32,IF(AY13<=15,24,16)) -> 24
A14: MinnieLoucas | B14: 6 | C14: 2 | D14: 14 | E14: 7 | F14: 4 | G14: 1 | H14: 1 | I14: 10 | J14: 15 | K14: 4 | L14: 11 | AY14: =COUNTIF(B14:AX14,"<>") -> 11 | AZ14: =IF(AY14<=5,32,IF(AY14<=15,24,16)) -> 24
A15: Nicolas | B15: 9 | C15: 5 | D15: 5 | E15: 5 | F15: 2 | H15: 6 | I15: 7 | J15: 7 | K15: 9 | L15: 9 | AY15: =COUNTIF(B15:AX15,"<>") -> 10 | AZ15: =IF(AY15<=5,32,IF(AY15<=15,24,16)) -> 24
A16: Patrice | B16: 1 | C16: 8 | D16: 11 | E16: 11 | F16: 5 | G16: 2 | H16: 7 | J16: 9 | K16: 15 | L16: 4 | AY16: =COUNTIF(B16:AX16,"<>") -> 10 | AZ16: =IF(AY16<=5,32,IF(AY16<=15,24,16)) -> 24
A17: Phoenix | B17: 11 | C17: 3 | D17: 12 | E17: 3 | F17: 8 | G17: 10 | H17: 8 | I17: 6 | J17: 14 | K17: 13 | L17: 6 | AY17: =COUNTIF(B17:AX17,"<>") -> 11 | AZ17: =IF(AY17<=5,32,IF(AY17<=15,24,16)) -> 24
A18: Ronkout | B18: 10 | C18: 4 | E18: 9 | F18: 7 | G18: 12 | H18: 16 | I18: 1 | J18: 5 | K18: 1 | AY18: =COUNTIF(B18:AX18,"<>") -> 9 | AZ18: =IF(AY18<=5,32,IF(AY18<=15,24,16)) -> 24
A19: Schirou | B19: 4 | C19: 7 | D19: 7 | E19: 2 | F19: 3 | H19: 9 | I19: 4 | J19: 2 | K19: 11 | L19: 8 | AY19: =COUNTIF(B19:AX19,"<>") -> 10 | AZ19: =IF(AY19<=5,32,IF(AY19<=15,24,16)) -> 24
A20: Falzarr | F20: 11 | AY20: =COUNTIF(B20:AX20,"<>") -> 1 | AZ20: =IF(AY20<=5,32,IF(AY20<=15,24,16)) -> 32
A21: PikaJul | G21: 3 | H21: 15 | J21: 1 | K21: 10 | AY21: =COUNTIF(B21:AX21,"<>") -> 4 | AZ21: =IF(AY21<=5,32,IF(AY21<=15,24,16)) -> 32
A22: Teddy | G22: 4 | H22: 10 | J22: 4 | K22: 3 | AY22: =COUNTIF(B22:AX22,"<>") -> 4 | AZ22: =IF(AY22<=5,32,IF(AY22<=15,24,16)) -> 32
A23: Benoît | G23: 5 | H23: 11 | J23: 12 | K23: 6 | AY23: =COUNTIF(B23:AX23,"<>") -> 4 | AZ23: =IF(AY23<=5,32,IF(AY23<=15,24,16)) -> 32
A24: Popa'akatuki | K24: 5 | AY24: =COUNTIF(B24:AX24,"<>") -> 1 | AZ24: =IF(AY24<=5,32,IF(AY24<=15,24,16)) -> 32
A25: Jerem | L25: 7 | AY25: =COUNTIF(B25:AX25,"<>") -> 1 | AZ25: =IF(AY25<=5,32,IF(AY25<=15,24,16)) -> 32
AY26: =COUNTIF(B26:AX26,"<>") -> 0 | AZ26: =IF(AY26<=5,32,IF(AY26<=15,24,16)) -> 32
AY27: =COUNTIF(B27:AX27,"<>") -> 0 | AZ27: =IF(AY27<=5,32,IF(AY27<=15,24,16)) -> 32
AY28: =COUNTIF(B28:AX28,"<>") -> 0 | AZ28: =IF(AY28<=5,32,IF(AY28<=15,24,16)) -> 32
AY29: =COUNTIF(B29:AX29,"<>") -> 0 | AZ29: =IF(AY29<=5,32,IF(AY29<=15,24,16)) -> 32
AY30: =COUNTIF(B30:AX30,"<>") -> 0 | AZ30: =IF(AY30<=5,32,IF(AY30<=15,24,16)) -> 32
AY31: =COUNTIF(B31:AX31,"<>") -> 0 | AZ31: =IF(AY31<=5,32,IF(AY31<=15,24,16)) -> 32
AY32: =COUNTIF(B32:AX32,"<>") -> 0 | AZ32: =IF(AY32<=5,32,IF(AY32<=15,24,16)) -> 32
AY33: =COUNTIF(B33:AX33,"<>") -> 0 | AZ33: =IF(AY33<=5,32,IF(AY33<=15,24,16)) -> 32
AY34: =COUNTIF(B34:AX34,"<>") -> 0 | AZ34: =IF(AY34<=5,32,IF(AY34<=15,24,16)) -> 32
AY35: =COUNTIF(B35:AX35,"<>") -> 0 | AZ35: =IF(AY35<=5,32,IF(AY35<=15,24,16)) -> 32
AY36: =COUNTIF(B36:AX36,"<>") -> 0 | AZ36: =IF(AY36<=5,32,IF(AY36<=15,24,16)) -> 32
AY37: =COUNTIF(B37:AX37,"<>") -> 0 | AZ37: =IF(AY37<=5,32,IF(AY37<=15,24,16)) -> 32
... AY104: =COUNTIF(B104:AX104,"<>") -> 0 | AZ104: =IF(AY104<=5,32,IF(AY104<=15,24,16)) -> 32

Sheet Feuil1
A1: Nouveau Elo = R+K×(S−E) R = ancien ELO du joueur K = constante de progression (par ex. 32 ou 24 selon la préférence) S = √(Nb_Joueurs + 1) / Position -> score réel (place dans le tournoi) E = 1 / (1 + 10^((Elo_Moyen - Elo_Precedent)/400)) -> score attendu
A2: Formule : Nouveau ELO = Elo_Precedent + K * (√(Nb_Joueurs + 1) / Position - 1 / (1 + 10^((Elo_Moyen - Elo_Precedent)/400)))
A3: Nom du joueur | B3: Elo de départ | C3: 45903 | D3: 45910 | E3: 45917 | F3: 45924 | G3: 45931 | H3: 45938 | I3: 45945 | J3: 45952 | K3: 45959 | L3: 45966 | M3: 45973 | N3: 45980 | O3: 45987 | P3: 45994 | Q3: 46001 | R3: 46008 | S3: 46015 | T3: 46022 | U3: 46029 | V3: 46036 | W3: 46043 | X3: 46050 | Y3: 46057 | Z3: 46064 | AA3: 46071 | AB3: 46078 | AC3: 46085 | AD3: 46092 | AE3: 46099 | AF3: 46106 | AG3: 46113 | AH3: 46120 | AI3: 46127 | AJ3: 46134 | AK3: 46141 | AL3: 46148 | AM3: 46155 | AN3: 46162 | AO3: 46169 | AP3: 46176 | AQ3: 46183 | AR3: 46190 | AS3: 46197 | AT3: 46204 | AU3: 46211 | AV3: 46218 | AW3: 46225 | AX3: 46232 | AY3: 46239 | AZ3: Classement ELO actuel
A4: =IF('Résultats des tournois'!A4="","",'Résultats des tournois'!A4) -> Breizhkanaki | B4: 1500 | C4: =IF('Résultats des tournois'!B4="","",B4+'K dynamique'!B4*((SQRT('Résultats des tournois'!B$2+1)/'Résultats des tournois'!B4)-(1/(1+10^((B4-B4)/400))))) -> 1507.9466 | D4: =IFERROR(__xludf.DUMMYFUNCTION("IF('Résultats des tournois'!C$2=0,"""",LET( lastVal, INDEX(FILTER($B4:C4, ISNUMBER($B4:C4)), COUNTA(FILTER($B4:C4, ISNUMBER($B4:C4)))), IFERROR( IF('Résultats des tournois'!C4="""", INDEX(FILTER($C4:C4, ISNUMBER($C4:C4)), COUNTA(FILTER($C4:C4, ISNUMBER($C"&"4:C4)))), lastVal + 'K dynamique'!C4 * ((SQRT('Résultats des tournois'!C$2 + 1)/'Résultats des tournois'!C4) - (1 / (1 + 10^((C$103 - lastVal)/400))))) ) ))"),1502.2700363466809) -> 1502.27 | E4: =IFERROR(__xludf.DUMMYFUNCTION("IF('Résultats des tournois'!D$2=0,"""",LET( lastVal, INDEX(FILTER($B4:D4, ISNUMBER($B4:D4)), COUNTA(FILTER($B4:D4, ISNUMBER($B4:D4)))), IFERROR( IF('Résultats des tournois'!D4="""", INDEX(FILTER($C4:D4, ISNUMBER($C4:D4)), COUNTA(FILTER($C4:D4, ISNUMBER($C"&"4:D4)))), lastVal + 'K dynamique'!D4 * ((SQRT('Résultats des tournois'!D$2 + 1)/'Résultats des tournois'!D4) - (1 / (1 + 10^((D$103 - lastVal)/400))))) ) ))"),1499.649282283463) -> 1499.6493 | F4: =IFERROR(__xludf.DUMMYFUNCTION("IF('Résultats des tournois'!E$2=0,"""",LET( lastVal, INDEX(FILTER($B4:E4, ISNUMBER($B4:E4)), COUNTA(FILTER($B4:E4, ISNUMBER($B4:E4)))), IFERROR( IF('Résultats des tournois'!E4="""", INDEX(FILTER($C4:E4, ISNUMBER($C4:E4)), COUNTA(FILTER($C4:E4, ISNUMBER($C"&"4:E4)))), lastVal + 'K dynamique'!E4 * ((SQRT('Résultats des tournois'!E$2 + 1)/'Résultats des tournois'!E4) - (1 / (1 + 10^((E$103 - lastVal)/400))))) ) ))"),1498.9897046746478) -> 1498.9897 | G4: =IFERROR(__xludf.DUMMYFUNCTION("IF('Résultats des tournois'!F$2=0,"""",LET( lastVal, INDEX(FILTER($B4:F4, ISNUMBER($B4:F4)), COUNTA(FILTER($B4:F4, ISNUMBER($B4:F4)))), IFERROR( IF('Résultats des tournois'!F4="""", INDEX(FILTER($C4:F4, ISNUMBER($C4:F4)), COUNTA(FILTER($C4:F4, ISNUMBER($C"&"4:F4)))), lastVal + 'K dynamique'!F4 * ((SQRT('Résultats des tournois'!F$2 + 1)/'Résultats des tournois'!F4) - (1 / (1 + 10^((F$103 - lastVal)/400))))) ) ))"),1498.9897046746478) -> 1498.9897 | H4: =IFERROR(__xludf.DUMMYFUNCTION("IF('Résultats des tournois'!G$2=0,"""",LET( lastVal, INDEX(FILTER($B4:G4, ISNUMBER($B4:G4)), COUNTA(FILTER($B4:G4, ISNUMBER($B4:G4)))), IFERROR( IF('Résultats des tournois'!G4="""", INDEX(FILTER($C4:G4, ISNUMBER($C4:G4)), COUNTA(FILTER($C4:G4, ISNUMBER($C"&"4:G4)))), lastVal + 'K dynamique'!G4 * ((SQRT('Résultats des tournois'!G$2 + 1)/'Résultats des tournois'!G4) - (1 / (1 + 10^((G$103 - lastVal)/400))))) ) ))"),1504.4939788449126) -> 1504.494 | I4: =IFERROR(__xludf.DUMMYFUNCTION("IF('Résultats des tournois'!H$2=0,"""",LET( lastVal, INDEX(FILTER($B4:H4, ISNUMBER($B4:H4)), COUNTA(FILTER($B4:H4, ISNUMBER($B4:H4)))), IFERROR( IF('Résultats des tournois'!H4="""", INDEX(FILTER($C4:H4, ISNUMBER($C4:H4)), COUNTA(FILTER($C4:H4, ISNUMBER($C"&"4:H4)))), lastVal + 'K dynamique'!H4 * ((SQRT('Résultats des tournois'!H$2 + 1)/'Résultats des tournois'!H4) - (1 / (1 + 10^((H$103 - lastVal)/400))))) ) ))"),1513.7916235412072) -> 1513.7916 | J4: =IFERROR(__xludf.DUMMYFUNCTION("IF('Résultats des tournois'!I$2=0,"""",LET( lastVal, INDEX(FILTER($B4:I4, ISNUMBER($B4:I4)), COUNTA(FILTER($B4:I4, ISNUMBER($B4:I4)))), IFERROR( IF('Résultats des tournois'!I4="""", INDEX(FILTER($C4:I4, ISNUMBER($C4:I4)), COUNTA(FILTER($C4:I4, ISNUMBER($C"&"4:I4)))), lastVal + 'K dynamique'!I4 * ((SQRT('Résultats des tournois'!I$2 + 1)/'Résultats des tournois'!I4) - (1 / (1 + 10^((I$103 - lastVal)/400))))) ) ))"),1512.09711887037) -> 1512.0971 | K4: =IFERROR(__xludf.DUMMYFUNCTION("IF('Résultats des tournois'!J$2=0,"""",LET( lastVal, INDEX(FILTER($B4:J4, ISNUMBER($B4:J4)), COUNTA(FILTER($B4:J4, ISNUMBER($B4:J4)))), IFERROR( IF('Résultats des tournois'!J4="""", INDEX(FILTER($C4:J4, ISNUMBER($C4:J4)), COUNTA(FILTER($C4:J4, ISNUMBER($C"&"4:J4)))), lastVal + 'K dynamique'!J4 * ((SQRT('Résultats des tournois'!J$2 + 1)/'Résultats des tournois'!J4) - (1 / (1 + 10^((J$103 - lastVal)/400))))) ) ))"),1512.09711887037) -> 1512.0971 | L4: =IFERROR(__xludf.DUMMYFUNCTION("IF('Résultats des tournois'!K$2=0,"""",LET( lastVal, INDEX(FILTER($B4:K4, ISNUMBER($B4:K4)), COUNTA(FILTER($B4:K4, ISNUMBER($B4:K4)))), IFERROR( IF('Résultats des tournois'!K4="""", INDEX(FILTER($C4:K4, ISNUMBER($C4:K4)), COUNTA(FILTER($C4:K4, ISNUMBER($C"&"4:K4)))), lastVal + 'K dynamique'!K4 * ((SQRT('Résultats des tournois'!K$2 + 1)/'Résultats des tournois'!K4) - (1 / (1 + 10^((K$103 - lastVal)/400))))) ) ))"),1512.09711887037) -> 1512.0971 | M4: =IFERROR(__xludf.DUMMYFUNCTION("IF('Résultats des tournois'!L$2=0,"""",LET( lastVal, INDEX(FILTER($B4:L4, ISNUMBER($B4:L4)), COUNTA(FILTER($B4:L4, ISNUMBER($B4:L4)))), IFERROR( IF('Résultats des tournois'!L4="""", INDEX(FILTER($C4:L4, ISNUMBER($C4:L4)), COUNTA(FILTER($C4:L4, ISNUMBER($C"&"4:L4)))), lastVal + 'K dynamique'!L4 * ((SQRT('Résultats des tournois'!L$2 + 1)/'Résultats des tournois'!L4) - (1 / (1 + 10^((L$103 - lastVal)/400))))) ) ))"),1512.09711887037) -> 1512.0971 | N4: =IFERROR(__xludf.DUMMYFUNCTION("IF('Résultats des tournois'!M$2=0,"""",LET( lastVal, INDEX(FILTER($B4:M4, ISNUMBER($B4:M4)), COUNTA(FILTER($B4:M4, ISNUMBER($B4:M4)))), IFERROR( IF('Résultats des tournois'!M4="""", INDEX(FILTER($C4:M4, ISNUMBER($C4:M4)), COUNTA(FILTER($C4:M4, ISNUMBER($C"&"4:M4)))), lastVal + 'K dynamique'!M4 * ((SQRT('Résultats des tournois'!M$2 + 1)/'Résultats des tournois'!M4) - (1 / (1 + 10^((M$103 - lastVal)/400))))) ) ))"),"") | O4: =IFERROR(__xludf.DUMMYFUNCTION("IF('Résultats des tournois'!N$2=0,"""",LET( lastVal, INDEX(FILTER($B4:N4, ISNUMBER($B4:N4)), COUNTA(FILTER($B4:N4, ISNUMBER($B4:N4)))), IFERROR( IF('Résultats des tournois'!N4="""", INDEX(FILTER($C4:N4, ISNUMBER($C4:N4)), COUNTA(FILTER($C4:N4, ISNUMBER($C"&"4:N4)))), lastVal + 'K dynamique'!N4 * ((SQRT('Résultats des tournois'!N$2 + 1)/'Résultats des tournois'!N4) - (1 / (1 + 10^((N$103 - lastVal)/400))))) ) ))"),"") | P4: =IFERROR(__xludf.DUMMYFUNCTION("IF('Résultats des tournois'!O$2=0,"""",LET( lastVal, INDEX(FILTER($B4:O4, ISNUMBER($B4:O4)), COUNTA(FILTER($B4:O4, ISNUMBER($B4:O4)))), IFERROR( IF('Résultats des tournois'!O4="""", INDEX(FILTER($C4:O4, ISNUMBER($C4:O4)), COUNTA(FILTER($C4:O4, ISNUMBER($C"&"4:O4)))), lastVal + 'K dynamique'!O4 * ((SQRT('Résultats des tournois'!O$2 + 1)/'Résultats des tournois'!O4) - (1 / (1 + 10^((O$103 - lastVal)/400))))) ) ))"),"") | Q4: =IFERROR(__xludf.DUMMYFUNCTION("IF('Résultats des tournois'!P$2=0,"""",LET( lastVal, INDEX(FILTER($B4:P4, ISNUMBER($B4:P4)), COUNTA(FILTER($B4:P4, ISNUMBER($B4:P4)))), IFERROR( IF('Résultats des tournois'!P4="""", INDEX(FILTER($C4:P4, ISNUMBER($C4:P4)), COUNTA(FILTER($C4:P4, ISNUMBER($C"&"4:P4)))), lastVal + 'K dynamique'!P4 * ((SQRT('Résultats des tournois'!P$2 + 1)/'Résultats des tournois'!P4) - (1 / (1 + 10^((P$103 - lastVal)/400))))) ) ))"),"") | R4: =IFERROR(__xludf.DUMMYFUNCTION("IF('Résultats des tournois'!Q$2=0,"""",LET( lastVal, INDEX(FILTER($B4:Q4, ISNUMBER($B4:Q4)), COUNTA(FILTER($B4:Q4, ISNUMBER($B4:Q4)))), IFERROR( IF('Résultats des tournois'!Q4="""", INDEX(FILTER($C4:Q4, ISNUMBER($C4:Q4)), COUNTA(FILTER($C4:Q4, ISNUMBER($C"&"4:Q4)))), lastVal + 'K dynamique'!Q4 * ((SQRT('Résultats des tournois'!Q$2 + 1)/'Résultats des tournois'!Q4) - (1 / (1 + 10^((Q$103 - lastVal)/400))))) ) ))"),"") | S4: =IFERROR(__xludf.DUMMYFUNCTION("IF('Résultats des tournois'!R$2=0,"""",LET( lastVal, INDEX(FILTER($B4:R4, ISNUMBER($B4:R4)), COUNTA(FILTER($B4:R4, ISNUMBER($B4:R4)))), IFERROR( IF('Résultats des tournois'!R4="""", INDEX(FILTER($C4:R4, ISNUMBER($C4:R4)), COUNTA(FILTER($C4:R4, ISNUMBER($C"&"4:R4)))), lastVal + 'K dynamique'!R4 * ((SQRT('Résultats des tournois'!R$2 + 1)/'Résultats des tournois'!R4) - (1 / (1 + 10^((R$103 - lastVal)/400))))) ) ))"),"") | T4: =IFERROR(__xludf.DUMMYFUNCTION("IF('Résultats des tournois'!S$2=0,"""",LET( lastVal, INDEX(FILTER($B4:S4, ISNUMBER($B4:S4)), COUNTA(FILTER($B4:S4, ISNUMBER($B4:S4)))), IFERROR( IF('Résultats des tournois'!S4="""", INDEX(FILTER($C4:S4, ISNUMBER($C4:S4)), COUNTA(FILTER($C4:S4, ISNUMBER($C"&"4:S4)))), lastVal + 'K dynamique'!S4 * ((SQRT('Résultats des tournois'!S$2 + 1)/'Résultats des tournois'!S4) - (1 / (1 + 10^((S$103 - lastVal)/400))))) ) ))"),"") | U4: =IFERROR(__xludf.DUMMYFUNCTION("IF('Résultats des tournois'!T$2=0,"""",LET( lastVal, INDEX(FILTER($B4:T4, ISNUMBER($B4:T4)), COUNTA(FILTER($B4:T4, ISNUMBER($B4:T4)))), IFERROR( IF('Résultats des tournois'!T4="""", INDEX(FILTER($C4:T4, ISNUMBER($C4:T4)), COUNTA(FILTER($C4:T4, ISNUMBER($C"&"4:T4)))), lastVal + 'K dynamique'!T4 * ((SQRT('Résultats des tournois'!T$2 + 1)/'Résultats des tournois'!T4) - (1 / (1 + 10^((T$103 - lastVal)/400))))) ) ))"),"") | V4: =IFERROR(__xludf.DUMMYFUNCTION("IF('Résultats des tournois'!U$2=0,"""",LET( lastVal, INDEX(FILTER($B4:U4, ISNUMBER($B4:U4)), COUNTA(FILTER($B4:U4, ISNUMBER($B4:U4)))), IFERROR( IF('Résultats des tournois'!U4="""", INDEX(FILTER($C4:U4, ISNUMBER($C4:U4)), COUNTA(FILTER($C4:U4, ISNUMBER($C"&"4:U4)))), lastVal + 'K dynamique'!U4 * ((SQRT('Résultats des tournois'!U$2 + 1)/'Résultats des tournois'!U4) - (1 / (1 + 10^((U$103 - lastVal)/400))))) ) ))"),"") | W4: =IFERROR(__xludf.DUMMYFUNCTION("IF('Résultats des tournois'!V$2=0,"""",LET( lastVal, INDEX(FILTER($B4:V4, ISNUMBER($B4:V4)), COUNTA(FILTER($B4:V4, ISNUMBER($B4:V4)))), IFERROR( IF('Résultats des tournois'!V4="""", INDEX(FILTER($C4:V4, ISNUMBER($C4:V4)), COUNTA(FILTER($C4:V4, ISNUMBER($C"&"4:V4)))), lastVal + 'K dynamique'!V4 * ((SQRT('Résultats des tournois'!V$2 + 1)/'Résultats des tournois'!V4) - (1 / (1 + 10^((V$103 - lastVal)/400))))) ) ))"),"") | X4: =IFERROR(__xludf.DUMMYFUNCTION("IF('Résultats des tournois'!W$2=0,"""",LET( lastVal, INDEX(FILTER($B4:W4, ISNUMBER($B4:W4)), COUNTA(FILTER($B4:W4, ISNUMBER($B4:W4)))), IFERROR( IF('Résultats des tournois'!W4="""", INDEX(FILTER($C4:W4, ISNUMBER($C4:W4)), COUNTA(FILTER($C4:W4, ISNUMBER($C"&"4:W4)))), lastVal + 'K dynamique'!W4 * ((SQRT('Résultats des tournois'!W$2 + 1)/'Résultats des tournois'!W4) - (1 / (1 + 10^((W$103 - lastVal)/400))))) ) ))"),"") | Y4: =IFERROR(__xludf.DUMMYFUNCTION("IF('Résultats des tournois'!X$2=0,"""",LET( lastVal, INDEX(FILTER($B4:X4, ISNUMBER($B4:X4)), COUNTA(FILTER($B4:X4, ISNUMBER($B4:X4)))), IFERROR( IF('Résultats des tournois'!X4="""", INDEX(FILTER($C4:X4, ISNUMBER($C4:X4)), COUNTA(FILTER($C4:X4, ISNUMBER($C"&"4:X4)))), lastVal + 'K dynamique'!X4 * ((SQRT('Résultats des tournois'!X$2 + 1)/'Résultats des tournois'!X4) - (1 / (1 + 10^((X$103 - lastVal)/400))))) ) ))"),"") | Z4: =IFERROR(__xludf.DUMMYFUNCTION("IF('Résultats des tournois'!Y$2=0,"""",LET( lastVal, INDEX(FILTER($B4:Y4, ISNUMBER($B4:Y4)), COUNTA(FILTER($B4:Y4, ISNUMBER($B4:Y4)))), IFERROR( IF('Résultats des tournois'!Y4="""", INDEX(FILTER($C4:Y4, ISNUMBER($C4:Y4)), COUNTA(FILTER($C4:Y4, ISNUMBER($C"&"4:Y4)))), lastVal + 'K dynamique'!Y4 * ((SQRT('Résultats des tournois'!Y$2 + 1)/'Résultats des tournois'!Y4) - (1 / (1 + 10^((Y$103 - lastVal)/400))))) ) ))"),"") | AA4: =IFERROR(__xludf.DUMMYFUNCTION("IF('Résultats des tournois'!Z$2=0,"""",LET( lastVal, INDEX(FILTER($B4:Z4, ISNUMBER($B4:Z4)), COUNTA(FILTER($B4:Z4, ISNUMBER($B4:Z4)))), IFERROR( IF('Résultats des tournois'!Z4="""", INDEX(FILTER($C4:Z4, ISNUMBER($C4:Z4)), COUNTA(FILTER($C4:Z4, ISNUMBER($C"&"4:Z4)))), lastVal + 'K dynamique'!Z4 * ((SQRT('Résultats des tournois'!Z$2 + 1)/'Résultats des tournois'!Z4) - (1 / (1 + 10^((Z$103 - lastVal)/400))))) ) ))"),"") | AB4: =IFERROR(__xludf.DUMMYFUNCTION("IF('Résultats des tournois'!AA$2=0,"""",LET( lastVal, INDEX(FILTER($B4:AA4, ISNUMBER($B4:AA4)), COUNTA(FILTER($B4:AA4, ISNUMBER($B4:AA4)))), IFERROR( IF('Résultats des tournois'!AA4="""", INDEX(FILTER($C4:AA4, ISNUMBER($C4:AA4)), COUNTA(FILTER($C4:AA4, IS"&"NUMBER($C4:AA4)))), lastVal + 'K dynamique'!AA4 * ((SQRT('Résultats des tournois'!AA$2 + 1)/'Résultats des tournois'!AA4) - (1 / (1 + 10^((AA$103 - lastVal)/400))))) ) ))"),"") | AC4: =IFERROR(__xludf.DUMMYFUNCTION("IF('Résultats des tournois'!AB$2=0,"""",LET( lastVal, INDEX(FILTER($B4:AB4, ISNUMBER($B4:AB4)), COUNTA(FILTER($B4:AB4, ISNUMBER($B4:AB4)))), IFERROR( IF('Résultats des tournois'!AB4="""", INDEX(FILTER($C4:AB4, ISNUMBER($C4:AB4)), COUNTA(FILTER($C4:AB4, IS"&"NUMBER($C4:AB4)))), lastVal + 'K dynamique'!AB4 * ((SQRT('Résultats des tournois'!AB$2 + 1)/'Résultats des tournois'!AB4) - (1 / (1 + 10^((AB$103 - lastVal)/400))))) ) ))"),"") | AD4: =IFERROR(__xludf.DUMMYFUNCTION("IF('Résultats des tournois'!AC$2=0,"""",LET( lastVal, INDEX(FILTER($B4:AC4, ISNUMBER($B4:AC4)), COUNTA(FILTER($B4:AC4, ISNUMBER($B4:AC4)))), IFERROR( IF('Résultats des tournois'!AC4="""", INDEX(FILTER($C4:AC4, ISNUMBER($C4:AC4)), COUNTA(FILTER($C4:AC4, IS"&"NUMBER($C4:AC4)))), lastVal + 'K dynamique'!AC4 * ((SQRT('Résultats des tournois'!AC$2 + 1)/'Résultats des tournois'!AC4) - (1 / (1 + 10^((AC$103 - lastVal)/400))))) ) ))"),"") | AE4: =IFERROR(__xludf.DUMMYFUNCTION("IF('Résultats des tournois'!AD$2=0,"""",LET( lastVal, INDEX(FILTER($B4:AD4, ISNUMBER($B4:AD4)), COUNTA(FILTER($B4:AD4, ISNUMBER($B4:AD4)))), IFERROR( IF('Résultats des tournois'!AD4="""", INDEX(FILTER($C4:AD4, ISNUMBER($C4:AD4)), COUNTA(FILTER($C4:AD4, IS"&"NUMBER($C4:AD4)))), lastVal + 'K dynamique'!AD4 * ((SQRT('Résultats des tournois'!AD$2 + 1)/'Résultats des tournois'!AD4) - (1 / (1 + 10^((AD$103 - lastVal)/400))))) ) ))"),"") | AF4: =IFERROR(__xludf.DUMMYFUNCTION("IF('Résultats des tournois'!AE$2=0,"""",LET( lastVal, INDEX(FILTER($B4:AE4, ISNUMBER($B4:AE4)), COUNTA(FILTER($B4:AE4, ISNUMBER($B4:AE4)))), IFERROR( IF('Résultats des tournois'!AE4="""", INDEX(FILTER($C4:AE4, ISNUMBER($C4:AE4)), COUNTA(FILTER($C4:AE4, IS"&"NUMBER($C4:AE4)))), lastVal + 'K dynamique'!AE4 * ((SQRT('Résultats des tournois'!AE$2 + 1)/'Résultats des tournois'!AE4) - (1 / (1 + 10^((AE$103 - lastVal)/400))))) ) ))"),"") | AG4: =IFERROR(__xludf.DUMMYFUNCTION("IF('Résultats des tournois'!AF$2=0,"""",LET( lastVal, INDEX(FILTER($B4:AF4, ISNUMBER($B4:AF4)), COUNTA(FILTER($B4:AF4, ISNUMBER($B4:AF4)))), IFERROR( IF('Résultats des tournois'!AF4="""", INDEX(FILTER($C4:AF4, ISNUMBER($C4:AF4)), COUNTA(FILTER($C4:AF4, IS"&"NUMBER($C4:AF4)))), lastVal + 'K dynamique'!AF4 * ((SQRT('Résultats des tournois'!AF$2 + 1)/'Résultats des tournois'!AF4) - (1 / (1 + 10^((AF$103 - lastVal)/400))))) ) ))"),"") | AH4: =IFERROR(__xludf.DUMMYFUNCTION("IF('Résultats des tournois'!AG$2=0,"""",LET( lastVal, INDEX(FILTER($B4:AG4, ISNUMBER($B4:AG4)), COUNTA(FILTER($B4:AG4, ISNUMBER($B4:AG4)))), IFERROR( IF('Résultats des tournois'!AG4="""", INDEX(FILTER($C4:AG4, ISNUMBER($C4:AG4)), COUNTA(FILTER($C4:AG4, IS"&"NUMBER($C4:AG4)))), lastVal + 'K dynamique'!AG4 * ((SQRT('Résultats des tournois'!AG$2 + 1)/'Résultats des tournois'!AG4) - (1 / (1 + 10^((AG$103 - lastVal)/400))))) ) ))"),"") | AI4: =IFERROR(__xludf.DUMMYFUNCTION("IF('Résultats des tournois'!AH$2=0,"""",LET( lastVal, INDEX(FILTER($B4:AH4, ISNUMBER($B4:AH4)), COUNTA(FILTER($B4:AH4, ISNUMBER($B4:AH4)))), IFERROR( IF('Résultats des tournois'!AH4="""", INDEX(FILTER($C4:AH4, ISNUMBER($C4:AH4)), COUNTA(FILTER($C4:AH4, IS"&"NUMBER($C4:AH4)))), lastVal + 'K dynamique'!AH4 * ((SQRT('Résultats des tournois'!AH$2 + 1)/'Résultats des tournois'!AH4) - (1 / (1 + 10^((AH$103 - lastVal)/400))))) ) ))"),"") | AJ4: =IFERROR(__xludf.DUMMYFUNCTION("IF('Résultats des tournois'!AI$2=0,"""",LET( lastVal, INDEX(FILTER($B4:AI4, ISNUMBER($B4:AI4)), COUNTA(FILTER($B4:AI4, ISNUMBER($B4:AI4)))), IFERROR( IF('Résultats des tournois'!AI4="""", INDEX(FILTER($C4:AI4, ISNUMBER($C4:AI4)), COUNTA(FILTER($C4:AI4, IS"&"NUMBER($C4:AI4)))), lastVal + 'K dynamique'!AI4 * ((SQRT('Résultats des tournois'!AI$2 + 1)/'Résultats des tournois'!AI4) - (1 / (1 + 10^((AI$103 - lastVal)/400))))) ) ))"),"") | AK4: =IFERROR(__xludf.DUMMYFUNCTION("IF('Résultats des tournois'!AJ$2=0,"""",LET( lastVal, INDEX(FILTER($B4:AJ4, ISNUMBER($B4:AJ4)), COUNTA(FILTER($B4:AJ4, ISNUMBER($B4:AJ4)))), IFERROR( IF('Résultats des tournois'!AJ4="""", INDEX(FILTER($C4:AJ4, ISNUMBER($C4:AJ4)), COUNTA(FILTER($C4:AJ4, IS"&"NUMBER($C4:AJ4)))), lastVal + 'K dynamique'!AJ4 * ((SQRT('Résultats des tournois'!AJ$2 + 1)/'Résultats des tournois'!AJ4) - (1 / (1 + 10^((AJ$103 - lastVal)/400))))) ) ))"),"") | AL4: =IFERROR(__xludf.DUMMYFUNCTION("IF('Résultats des tournois'!AK$2=0,"""",LET( lastVal, INDEX(FILTER($B4:AK4, ISNUMBER($B4:AK4)), COUNTA(FILTER($B4:AK4, ISNUMBER($B4:AK4)))), IFERROR( IF('Résultats des tournois'!AK4="""", INDEX(FILTER($C4:AK4, ISNUMBER($C4:AK4)), COUNTA(FILTER($C4:AK4, IS"&"NUMBER($C4:AK4)))), lastVal + 'K dynamique'!AK4 * ((SQRT('Résultats des tournois'!AK$2 + 1)/'Résultats des tournois'!AK4) - (1 / (1 + 10^((AK$103 - lastVal)/400))))) ) ))"),"") | AM4: =IFERROR(__xludf.DUMMYFUNCTION("IF('Résultats des tournois'!AL$2=0,"""",LET( lastVal, INDEX(FILTER($B4:AL4, ISNUMBER($B4:AL4)), COUNTA(FILTER($B4:AL4, ISNUMBER($B4:AL4)))), IFERROR( IF('Résultats des tournois'!AL4="""", INDEX(FILTER($C4:AL4, ISNUMBER($C4:AL4)), COUNTA(FILTER($C4:AL4, IS"&"NUMBER($C4:AL4)))), lastVal + 'K dynamique'!AL4 * ((SQRT('Résultats des tournois'!AL$2 + 1)/'Résultats des tournois'!AL4) - (1 / (1 + 10^((AL$103 - lastVal)/400))))) ) ))"),"") | AN4: =IFERROR(__xludf.DUMMYFUNCTION("IF('Résultats des tournois'!AM$2=0,"""",LET( lastVal, INDEX(FILTER($B4:AM4, ISNUMBER($B4:AM4)), COUNTA(FILTER($B4:AM4, ISNUMBER($B4:AM4)))), IFERROR( IF('Résultats des tournois'!AM4="""", INDEX(FILTER($C4:AM4, ISNUMBER($C4:AM4)), COUNTA(FILTER($C4:AM4, IS"&"NUMBER($C4:AM4)))), lastVal + 'K dynamique'!AM4 * ((SQRT('Résultats des tournois'!AM$2 + 1)/'Résultats des tournois'!AM4) - (1 / (1 + 10^((AM$103 - lastVal)/400))))) ) ))"),"") | AO4: =IFERROR(__xludf.DUMMYFUNCTION("IF('Résultats des tournois'!AN$2=0,"""",LET( lastVal, INDEX(FILTER($B4:AN4, ISNUMBER($B4:AN4)), COUNTA(FILTER($B4:AN4, ISNUMBER($B4:AN4)))), IFERROR( IF('Résultats des tournois'!AN4="""", INDEX(FILTER($C4:AN4, ISNUMBER($C4:AN4)), COUNTA(FILTER($C4:AN4, IS"&"NUMBER($C4:AN4)))), lastVal + 'K dynamique'!AN4 * ((SQRT('Résultats des tournois'!AN$2 + 1)/'Résultats des tournois'!AN4) - (1 / (1 + 10^((AN$103 - lastVal)/400))))) ) ))"),"") | AP4: =IFERROR(__xludf.DUMMYFUNCTION("IF('Résultats des tournois'!AO$2=0,"""",LET( lastVal, INDEX(FILTER($B4:AO4, ISNUMBER($B4:AO4)), COUNTA(FILTER($B4:AO4, ISNUMBER($B4:AO4)))), IFERROR( IF('Résultats des tournois'!AO4="""", INDEX(FILTER($C4:AO4, ISNUMBER($C4:AO4)), COUNTA(FILTER($C4:AO4, IS"&"NUMBER($C4:AO4)))), lastVal + 'K dynamique'!AO4 * ((SQRT('Résultats des tournois'!AO$2 + 1)/'Résultats des tournois'!AO4) - (1 / (1 + 10^((AO$103 - lastVal)/400))))) ) ))"),"") | AQ4: =IFERROR(__xludf.DUMMYFUNCTION("IF('Résultats des tournois'!AP$2=0,"""",LET( lastVal, INDEX(FILTER($B4:AP4, ISNUMBER($B4:AP4)), COUNTA(FILTER($B4:AP4, ISNUMBER($B4:AP4)))), IFERROR( IF('Résultats des tournois'!AP4="""", INDEX(FILTER($C4:AP4, ISNUMBER($C4:AP4)), COUNTA(FILTER($C4:AP4, IS"&"NUMBER($C4:AP4)))), lastVal + 'K dynamique'!AP4 * ((SQRT('Résultats des tournois'!AP$2 + 1)/'Résultats des tournois'!AP4) - (1 / (1 + 10^((AP$103 - lastVal)/400))))) ) ))"),"") | AR4: =IFERROR(__xludf.DUMMYFUNCTION("IF('Résultats des tournois'!AQ$2=0,"""",LET( lastVal, INDEX(FILTER($B4:AQ4, ISNUMBER($B4:AQ4)), COUNTA(FILTER($B4:AQ4, ISNUMBER($B4:AQ4)))), IFERROR( IF('Résultats des tournois'!AQ4="""", INDEX(FILTER($C4:AQ4, ISNUMBER($C4:AQ4)), COUNTA(FILTER($C4:AQ4, IS"&"NUMBER($C4:AQ4)))), lastVal + 'K dynamique'!AQ4 * ((SQRT('Résultats des tournois'!AQ$2 + 1)/'Résultats des tournois'!AQ4) - (1 / (1 + 10^((AQ$103 - lastVal)/400))))) ) ))"),"") | AS4: =IFERROR(__xludf.DUMMYFUNCTION("IF('Résultats des tournois'!AR$2=0,"""",LET( lastVal, INDEX(FILTER($B4:AR4, ISNUMBER($B4:AR4)), COUNTA(FILTER($B4:AR4, ISNUMBER($B4:AR4)))), IFERROR( IF('Résultats des tournois'!AR4="""", INDEX(FILTER($C4:AR4, ISNUMBER($C4:AR4)), COUNTA(FILTER($C4:AR4, IS"&"NUMBER($C4:AR4)))), lastVal + 'K dynamique'!AR4 * ((SQRT('Résultats des tournois'!AR$2 + 1)/'Résultats des tournois'!AR4) - (1 / (1 + 10^((AR$103 - lastVal)/400))))) ) ))"),"") | AT4: =IFERROR(__xludf.DUMMYFUNCTION("IF('Résultats des tournois'!AS$2=0,"""",LET( lastVal, INDEX(FILTER($B4:AS4, ISNUMBER($B4:AS4)), COUNTA(FILTER($B4:AS4, ISNUMBER($B4:AS4)))), IFERROR( IF('Résultats des tournois'!AS4="""", INDEX(FILTER($C4:AS4, ISNUMBER($C4:AS4)), COUNTA(FILTER($C4:AS4, IS"&"NUMBER($C4:AS4)))), lastVal + 'K dynamique'!AS4 * ((SQRT('Résultats des tournois'!AS$2 + 1)/'Résultats des tournois'!AS4) - (1 / (1 + 10^((AS$103 - lastVal)/400))))) ) ))"),"") | AU4: =IFERROR(__xludf.DUMMYFUNCTION("IF('Résultats des tournois'!AT$2=0,"""",LET( lastVal, INDEX(FILTER($B4:AT4, ISNUMBER($B4:AT4)), COUNTA(FILTER($B4:AT4, ISNUMBER($B4:AT4)))), IFERROR( IF('Résultats des tournois'!AT4="""", INDEX(FILTER($C4:AT4, ISNUMBER($C4:AT4)), COUNTA(FILTER($C4:AT4, IS"&"NUMBER($C4:AT4)))), lastVal + 'K dynamique'!AT4 * ((SQRT('Résultats des tournois'!AT$2 + 1)/'Résultats des tournois'!AT4) - (1 / (1 + 10^((AT$103 - lastVal)/400))))) ) ))"),"") | AV4: =IFERROR(__xludf.DUMMYFUNCTION("IF('Résultats des tournois'!AU$2=0,"""",LET( lastVal, INDEX(FILTER($B4:AU4, ISNUMBER($B4:AU4)), COUNTA(FILTER($B4:AU4, ISNUMBER($B4:AU4)))), IFERROR( IF('Résultats des tournois'!AU4="""", INDEX(FILTER($C4:AU4, ISNUMBER($C4:AU4)), COUNTA(FILTER($C4:AU4, IS"&"NUMBER($C4:AU4)))), lastVal + 'K dynamique'!AU4 * ((SQRT('Résultats des tournois'!AU$2 + 1)/'Résultats des tournois'!AU4) - (1 / (1 + 10^((AU$103 - lastVal)/400))))) ) ))"),"") | AW4: =IFERROR(__xludf.DUMMYFUNCTION("IF('Résultats des tournois'!AV$2=0,"""",LET( lastVal, INDEX(FILTER($B4:AV4, ISNUMBER($B4:AV4)), COUNTA(FILTER($B4:AV4, ISNUMBER($B4:AV4)))), IFERROR( IF('Résultats des tournois'!AV4="""", INDEX(FILTER($C4:AV4, ISNUMBER($C4:AV4)), COUNTA(FILTER($C4:AV4, IS"&"NUMBER($C4:AV4)))), lastVal + 'K dynamique'!AV4 * ((SQRT('Résultats des tournois'!AV$2 + 1)/'Résultats des tournois'!AV4) - (1 / (1 + 10^((AV$103 - lastVal)/400))))) ) ))"),"") | AX4: =IFERROR(__xludf.DUMMYFUNCTION("IF('Résultats des tournois'!AW$2=0,"""",LET( lastVal, INDEX(FILTER($B4:AW4, ISNUMBER($B4:AW4)), COUNTA(FILTER($B4:AW4, ISNUMBER($B4:AW4)))), IFERROR( IF('Résultats des tournois'!AW4="""", INDEX(FILTER($C4:AW4, ISNUMBER($C4:AW4)), COUNTA(FILTER($C4:AW4, IS"&"NUMBER($C4:AW4)))), lastVal + 'K dynamique'!AW4 * ((SQRT('Résultats des tournois'!AW$2 + 1)/'Résultats des tournois'!AW4) - (1 / (1 + 10^((AW$103 - lastVal)/400))))) ) ))"),"") | AY4: =IFERROR(__xludf.DUMMYFUNCTION("IF('Résultats des tournois'!AX$2=0,"""",LET( lastVal, INDEX(FILTER($B4:AX4, ISNUMBER($B4:AX4)), COUNTA(FILTER($B4:AX4, ISNUMBER($B4:AX4)))), IFERROR( IF('Résultats des tournois'!AX4="""", INDEX(FILTER($C4:AX4, ISNUMBER($C4:AX4)), COUNTA(FILTER($C4:AX4, IS"&"NUMBER($C4:AX4)))), lastVal + 'K dynamique'!AX4 * ((SQRT('Résultats des tournois'!AX$2 + 1)/'Résultats des tournois'!AX4) - (1 / (1 + 10^((AX$103 - lastVal)/400))))) ) ))"),"") | AZ4: {=IF(MAX(($C4:AY4<>"")*COLUMN($C4:AY4))=0,"",INDEX($C4:AY4,1,MAX(($C4:AY4<>"")*COLUMN($C4:AY4))-COLUMN($C4)+1))} -> 1512.0971 | BA4: =IF(ISNUMBER(AZ4),RANK(AZ4,$AZ$4:$AZ$102,0),"") -> 17
